Starting Klippy...
Args: ['/home/kkobold/klipper/klippy/klippy.py', '/home/kkobold/printer_data/config/printer.cfg', '-I', '/home/kkobold/printer_data/comms/klippy.serial', '-l', '/home/kkobold/printer_data/logs/klippy.log', '-a', '/home/kkobold/printer_data/comms/klippy.sock']
Git version: 'v0.12.0-267-g12cd1d9e'
Branch: master
Remote: origin
Tracked URL: https://github.com/Klipper3d/klipper
CPU: 4 core ?
Python: '3.9.2 (default, Feb 28 2021, 17:03:44) \n[GCC 10.2.1 20210110]'
Building C code module c_helper.so
Start printer at Thu Jul 18 18:52:09 2024 (1721339529.4 1131.6)
===== Config file =====
[mcu]
serial = /dev/serial/by-id/<your-mcu-id>

[virtual_sdcard]
path = /home/kkobold/printer_data/gcodes
on_error_gcode = CANCEL_PRINT

[printer]
kinematics = none
max_velocity = 1000
max_accel = 1000
=======================
mcu 'mcu': Starting serial connect
mcu 'mcu': Unable to open serial port: [Errno 2] could not open port /dev/serial/by-id/<your-mcu-id>: [Errno 2] No such file or directory: '/dev/serial/by-id/<your-mcu-id>'
mcu 'mcu': Unable to open serial port: [Errno 2] could not open port /dev/serial/by-id/<your-mcu-id>: [Errno 2] No such file or directory: '/dev/serial/by-id/<your-mcu-id>'
mcu 'mcu': Unable to open serial port: [Errno 2] could not open port /dev/serial/by-id/<your-mcu-id>: [Errno 2] No such file or directory: '/dev/serial/by-id/<your-mcu-id>'
mcu 'mcu': Unable to open serial port: [Errno 2] could not open port /dev/serial/by-id/<your-mcu-id>: [Errno 2] No such file or directory: '/dev/serial/by-id/<your-mcu-id>'
mcu 'mcu': Unable to open serial port: [Errno 2] could not open port /dev/serial/by-id/<your-mcu-id>: [Errno 2] No such file or directory: '/dev/serial/by-id/<your-mcu-id>'
mcu 'mcu': Unable to open serial port: [Errno 2] could not open port /dev/serial/by-id/<your-mcu-id>: [Errno 2] No such file or directory: '/dev/serial/by-id/<your-mcu-id>'
mcu 'mcu': Unable to open serial port: [Errno 2] could not open port /dev/serial/by-id/<your-mcu-id>: [Errno 2] No such file or directory: '/dev/serial/by-id/<your-mcu-id>'
mcu 'mcu': Unable to open serial port: [Errno 2] could not open port /dev/serial/by-id/<your-mcu-id>: [Errno 2] No such file or directory: '/dev/serial/by-id/<your-mcu-id>'
mcu 'mcu': Unable to open serial port: [Errno 2] could not open port /dev/serial/by-id/<your-mcu-id>: [Errno 2] No such file or directory: '/dev/serial/by-id/<your-mcu-id>'
mcu 'mcu': Unable to open serial port: [Errno 2] could not open port /dev/serial/by-id/<your-mcu-id>: [Errno 2] No such file or directory: '/dev/serial/by-id/<your-mcu-id>'
mcu 'mcu': Unable to open serial port: [Errno 2] could not open port /dev/serial/by-id/<your-mcu-id>: [Errno 2] No such file or directory: '/dev/serial/by-id/<your-mcu-id>'
mcu 'mcu': Unable to open serial port: [Errno 2] could not open port /dev/serial/by-id/<your-mcu-id>: [Errno 2] No such file or directory: '/dev/serial/by-id/<your-mcu-id>'
mcu 'mcu': Unable to open serial port: [Errno 2] could not open port /dev/serial/by-id/<your-mcu-id>: [Errno 2] No such file or directory: '/dev/serial/by-id/<your-mcu-id>'
mcu 'mcu': Unable to open serial port: [Errno 2] could not open port /dev/serial/by-id/<your-mcu-id>: [Errno 2] No such file or directory: '/dev/serial/by-id/<your-mcu-id>'
mcu 'mcu': Unable to open serial port: [Errno 2] could not open port /dev/serial/by-id/<your-mcu-id>: [Errno 2] No such file or directory: '/dev/serial/by-id/<your-mcu-id>'
mcu 'mcu': Unable to open serial port: [Errno 2] could not open port /dev/serial/by-id/<your-mcu-id>: [Errno 2] No such file or directory: '/dev/serial/by-id/<your-mcu-id>'
mcu 'mcu': Unable to open serial port: [Errno 2] could not open port /dev/serial/by-id/<your-mcu-id>: [Errno 2] No such file or directory: '/dev/serial/by-id/<your-mcu-id>'
mcu 'mcu': Unable to open serial port: [Errno 2] could not open port /dev/serial/by-id/<your-mcu-id>: [Errno 2] No such file or directory: '/dev/serial/by-id/<your-mcu-id>'
MCU error during connect
Traceback (most recent call last):
  File "/home/kkobold/klipper/klippy/mcu.py", line 793, in _mcu_identify
    self._serial.connect_uart(self._serialport, self._baud, rts)
  File "/home/kkobold/klipper/klippy/serialhdl.py", line 183, in connect_uart
    self._error("Unable to connect")
  File "/home/kkobold/klipper/klippy/serialhdl.py", line 61, in _error
    raise error(self.warn_prefix + (msg % params))
serialhdl.error: mcu 'mcu': Unable to connect

During handling of the above exception, another exception occurred:

Traceback (most recent call last):
  File "/home/kkobold/klipper/klippy/klippy.py", line 131, in _connect
    self.send_event("klippy:mcu_identify")
  File "/home/kkobold/klipper/klippy/klippy.py", line 223, in send_event
    return [cb(*params) for cb in self.event_handlers.get(event, [])]
  File "/home/kkobold/klipper/klippy/klippy.py", line 223, in <listcomp>
    return [cb(*params) for cb in self.event_handlers.get(event, [])]
  File "/home/kkobold/klipper/klippy/mcu.py", line 798, in _mcu_identify
    raise error(str(e))
mcu.error: mcu 'mcu': Unable to connect
mcu 'mcu': Unable to connect
Once the underlying issue is corrected, use the
"FIRMWARE_RESTART" command to reset the firmware, reload the
config, and restart the host software.
Error configuring printer

No build file /home/kkobold/klipper/klippy/../.config
No build file /home/kkobold/klipper/klippy/../out/klipper.dict
No build file /home/kkobold/klipper/klippy/../out/klipper.elf
webhooks client 281473703158592: New connection
webhooks client 281473703158592: Client info {'program': 'Moonraker', 'version': 'v0.8.0-385-gdc00d38'}
webhooks client 281473703158592: Disconnected
webhooks client 281473705469552: New connection
webhooks client 281473705469552: Client info {'program': 'Moonraker', 'version': 'v0.8.0-385-gdc00d38'}
